<?xml version="1.0"?>
<!-- =================================================================================== -->
<!-- |    This document was autogenerated by xacro from rosbot_xl.urdf.xacro           | -->
<!-- |    EDITING THIS FILE BY HAND IS NOT RECOMMENDED                                 | -->
<!-- =================================================================================== -->
<robot name="rosbot_xl">
  <link name="base_link" />
  <joint name="base_to_body_joint" type="fixed">
    <origin rpy="0.0 0.0 0.0" xyz="0.0 0.0 0.048" />
    <parent link="base_link" />
    <child link="body_link" />
  </joint>
  <link name="body_link">
    <visual>
      <geometry>
        <mesh filename="file:///robot_models/rosbotxl/meshes/body.dae" scale="1 1 1" />
      </geometry>
      <origin rpy="0.0 0.0 0.0" xyz="0.0 0.0 0.0" />
    </visual>
    <collision>
      <geometry>
        <mesh filename="file:///robot_models/rosbotxl/meshes/body_colision.stl" scale="1 1 1" />
      </geometry>
      <origin rpy="0.0 0.0 0.0" xyz="0.0 0.0 0.0" />
    </collision>
    <inertial>
      <mass value="3.5" />
      <origin rpy="0.0 0.0 0.0" xyz="-0.016319 -0.004036 0.02819" />
      <inertia ixx="0.0254042524427888" ixy="-0.0002000608350169362" ixz="-0.0009754256573561553" iyy="0.028746423126319035" iyz="-0.0002603325647592511" izz="0.046227102375569866" />
    </inertial>
  </link>
  <joint name="body_to_cover_joint" type="fixed">
    <origin rpy="0.0 0.0 0.0" xyz="0.0 0.0 0.08345" />
    <parent link="body_link" />
    <child link="cover_link" />
  </joint>
  <link name="cover_link" />
  <joint name="body_to_imu_joint" type="fixed">
    <origin rpy="3.14159 0.0 0.0" xyz="-0.1369 -0.0419 0.0370" />
    <parent link="body_link" />
    <child link="imu_link" />
  </joint>
  <link name="imu_link">
    <inertial>
      <mass value="0.0000001" />
      <inertia ixx="1" ixy="0" ixz="0" iyy="1" iyz="0" izz="1" />
    </inertial>
  </link>
  <joint name="fl_wheel_joint" type="continuous">
    <parent link="body_link" />
    <child link="fl_wheel_link" />
    <origin rpy="0.0 0.0 0.0" xyz="0.085 0.118 0.0" />
    <axis xyz="0.0 1.0 0.0" />
    <limit effort="1.2" velocity="21.0" />
    <dynamics damping="0.001" friction="0.001" />
  </joint>
  <link name="fl_wheel_link">
    <visual>
      <geometry>
        <mesh filename="file:///robot_models/rosbotxl/meshes/wheel_a.dae" scale="1 1 1" />
      </geometry>
      <origin rpy="0.0 0.0 0.0" xyz="0.0 0.0 0.0" />
    </visual>
    <collision>
      <geometry>
        <cylinder length="0.032" radius="0.048" />
      </geometry>
      <origin rpy="1.5707963267948966 0.0 0.0" xyz="0.0 0.0 0.0" />
      <surface>
        <!-- Surface settings based on https://github.com/gazebosim/gz-sim/blob/gz-sim7/examples/worlds/diff_drive_skid.sdf -->
        <friction>
          <ode>
            <mu>0.5</mu>
            <mu2>1.0</mu2>
            <fdir1>0 0 1</fdir1>
          </ode>
          <bullet>
            <friction>1</friction>
            <friction2>1</friction2>
            <rolling_friction>0.1</rolling_friction>
          </bullet>
        </friction>
      </surface>
    </collision>
    <inertial>
      <mass value="0.051" />
      <inertia ixx="3.954e-05" ixy="0.000" ixz="0.000" iyy="7.116e-05" iyz="0.000" izz="4.032e-05" />
    </inertial>
  </link>
  <joint name="fr_wheel_joint" type="continuous">
    <parent link="body_link" />
    <child link="fr_wheel_link" />
    <origin rpy="0.0 0.0 0.0" xyz="0.085 -0.118 0.0" />
    <axis xyz="0.0 1.0 0.0" />
    <limit effort="1.2" velocity="21.0" />
    <dynamics damping="0.001" friction="0.001" />
  </joint>
  <link name="fr_wheel_link">
    <visual>
      <geometry>
        <mesh filename="file:///robot_models/rosbotxl/meshes/wheel_b.dae" scale="1 1 1" />
      </geometry>
      <origin rpy="0.0 0.0 0.0" xyz="0.0 0.0 0.0" />
    </visual>
    <collision>
      <geometry>
        <cylinder length="0.032" radius="0.048" />
      </geometry>
      <origin rpy="1.5707963267948966 0.0 0.0" xyz="0.0 0.0 0.0" />
      <surface>
        <!-- Surface settings based on https://github.com/gazebosim/gz-sim/blob/gz-sim7/examples/worlds/diff_drive_skid.sdf -->
        <friction>
          <ode>
            <mu>0.5</mu>
            <mu2>1.0</mu2>
            <fdir1>0 0 1</fdir1>
          </ode>
          <bullet>
            <friction>1</friction>
            <friction2>1</friction2>
            <rolling_friction>0.1</rolling_friction>
          </bullet>
        </friction>
      </surface>
    </collision>
    <inertial>
      <mass value="0.051" />
      <inertia ixx="3.954e-05" ixy="0.000" ixz="0.000" iyy="7.116e-05" iyz="0.000" izz="4.032e-05" />
    </inertial>
  </link>
  <joint name="rl_wheel_joint" type="continuous">
    <parent link="body_link" />
    <child link="rl_wheel_link" />
    <origin rpy="0.0 0.0 0.0" xyz="-0.085 0.118 0.0" />
    <axis xyz="0.0 1.0 0.0" />
    <limit effort="1.2" velocity="21.0" />
    <dynamics damping="0.001" friction="0.001" />
  </joint>
  <link name="rl_wheel_link">
    <visual>
      <geometry>
        <mesh filename="file:///robot_models/rosbotxl/meshes/wheel_a.dae" scale="1 1 1" />
      </geometry>
      <origin rpy="0.0 0.0 0.0" xyz="0.0 0.0 0.0" />
    </visual>
    <collision>
      <geometry>
        <cylinder length="0.032" radius="0.048" />
      </geometry>
      <origin rpy="1.5707963267948966 0.0 0.0" xyz="0.0 0.0 0.0" />
      <surface>
        <!-- Surface settings based on https://github.com/gazebosim/gz-sim/blob/gz-sim7/examples/worlds/diff_drive_skid.sdf -->
        <friction>
          <ode>
            <mu>0.5</mu>
            <mu2>1.0</mu2>
            <fdir1>0 0 1</fdir1>
          </ode>
          <bullet>
            <friction>1</friction>
            <friction2>1</friction2>
            <rolling_friction>0.1</rolling_friction>
          </bullet>
        </friction>
      </surface>
    </collision>
    <inertial>
      <mass value="0.051" />
      <inertia ixx="3.954e-05" ixy="0.000" ixz="0.000" iyy="7.116e-05" iyz="0.000" izz="4.032e-05" />
    </inertial>
  </link>
  <joint name="rr_wheel_joint" type="continuous">
    <parent link="body_link" />
    <child link="rr_wheel_link" />
    <origin rpy="0.0 0.0 0.0" xyz="-0.085 -0.118 0.0" />
    <axis xyz="0.0 1.0 0.0" />
    <limit effort="1.2" velocity="21.0" />
    <dynamics damping="0.001" friction="0.001" />
  </joint>
  <link name="rr_wheel_link">
    <visual>
      <geometry>
        <mesh filename="file:///robot_models/rosbotxl/meshes/wheel_b.dae" scale="1 1 1" />
      </geometry>
      <origin rpy="0.0 0.0 0.0" xyz="0.0 0.0 0.0" />
    </visual>
    <collision>
      <geometry>
        <cylinder length="0.032" radius="0.048" />
      </geometry>
      <origin rpy="1.5707963267948966 0.0 0.0" xyz="0.0 0.0 0.0" />
      <surface>
        <!-- Surface settings based on https://github.com/gazebosim/gz-sim/blob/gz-sim7/examples/worlds/diff_drive_skid.sdf -->
        <friction>
          <ode>
            <mu>0.5</mu>
            <mu2>1.0</mu2>
            <fdir1>0 0 1</fdir1>
          </ode>
          <bullet>
            <friction>1</friction>
            <friction2>1</friction2>
            <rolling_friction>0.1</rolling_friction>
          </bullet>
        </friction>
      </surface>
    </collision>
    <inertial>
      <mass value="0.051" />
      <inertia ixx="3.954e-05" ixy="0.000" ixz="0.000" iyy="7.116e-05" iyz="0.000" izz="4.032e-05" />
    </inertial>
  </link>
  <ros2_control name="imu" type="sensor">
    <hardware>
      <plugin>rosbot_hardware_interfaces/RosbotImuSensor</plugin>
      <param name="connection_timeout_ms">120000</param>
      <param name="connection_check_period_ms">500</param>
    </hardware>
    <sensor name="imu">
      <state_interface name="orientation.x" />
      <state_interface name="orientation.y" />
      <state_interface name="orientation.z" />
      <state_interface name="orientation.w" />
      <state_interface name="angular_velocity.x" />
      <state_interface name="angular_velocity.y" />
      <state_interface name="angular_velocity.z" />
      <state_interface name="linear_acceleration.x" />
      <state_interface name="linear_acceleration.y" />
      <state_interface name="linear_acceleration.z" />
    </sensor>
  </ros2_control>
  <ros2_control name="wheels" type="system">
    <hardware>
      <plugin>rosbot_hardware_interfaces/RosbotSystem</plugin>
      <param name="connection_timeout_ms">120000</param>
      <param name="connection_check_period_ms">500</param>
      <!-- for some reason diff drive controller publishes velocities for motors in rad/s, but expects feedback in m/s
            both commands and feedback from digital board are in rad/s, so it is necessary to convert it
            maybe will be resolved (https://github.com/ros-controls/ros2_controllers/issues/411), then it can be removed -->
      <param name="wheel_radius">0.048</param>
      <!-- order of velocity commands to be published in motors_cmd Float32MultiArray msg -->
      <param name="velocity_command_joint_order">
                rr_wheel_joint,
                rl_wheel_joint,
                fr_wheel_joint,
                fl_wheel_joint
          </param>
    </hardware>
    <joint name="fl_wheel_joint">
      <command_interface name="velocity" />
      <state_interface name="position" />
      <state_interface name="velocity" />
    </joint>
    <joint name="fr_wheel_joint">
      <command_interface name="velocity" />
      <state_interface name="position" />
      <state_interface name="velocity" />
    </joint>
    <joint name="rl_wheel_joint">
      <command_interface name="velocity" />
      <state_interface name="position" />
      <state_interface name="velocity" />
    </joint>
    <joint name="rr_wheel_joint">
      <command_interface name="velocity" />
      <state_interface name="position" />
      <state_interface name="velocity" />
    </joint>
  </ros2_control>
  <joint name="cover_link_to_rplidar_s1_link_joint" type="fixed">
    <origin rpy="0.0 0.0 3.141592653589793" xyz="0.0 0.0 0.0" />
    <parent link="cover_link" />
    <child link="rplidar_s1_link" />
  </joint>
  <link name="rplidar_s1_link">
    <visual>
      <geometry>
        <mesh filename="file:///robot_models/rosbotxl/meshes/rplidar_s1.stl" scale="0.0001 0.0001 0.0001" />
      </geometry>
      <origin rpy="0.0 0.0 -1.5707963267948966" xyz="0.0 0.0 0.0255" />
      <material name="DarkGrey">
        <color rgba="0.05 0.05 0.05 1.0" />
      </material>
    </visual>
    <collision>
      <geometry>
        <cylinder length="0.051" radius="0.02775" />
      </geometry>
      <origin rpy="0.0 0.0 0.0" xyz="0.0 0.0 0.0255" />
    </collision>
    <inertial>
      <mass value="0.105" />
      <inertia ixx="1.0" ixy="0.0" ixz="0.0" iyy="1.0" iyz="0.0" izz="1.0" />
    </inertial>
  </link>
  <joint name="laser_joint" type="fixed">
    <origin rpy="0.0 0.0 0.0" xyz="0.0 0.0 0.04" />
    <parent link="rplidar_s1_link" />
    <child link="laser" />
  </joint>
  <link name="laser" />
  <gazebo reference="laser">
    <sensor name="rplidar_s1_sensor" type="gpu_lidar">
      <topic>/scan</topic>
      <frame_id>laser</frame_id>
      <ignition_frame_id>laser</ignition_frame_id>
      <update_rate>10.0</update_rate>
      <ray>
        <scan>
          <horizontal>
            <samples>9200</samples>
            <resolution>1</resolution>
            <min_angle>-3.141592653589793</min_angle>
            <max_angle>3.141592653589793</max_angle>
          </horizontal>
        </scan>
        <range>
          <min>0.04</min>
          <max>40.0</max>
          <resolution>0.03</resolution>
        </range>
        <noise>
          <type>gaussian</type>
          <mean>0.0</mean>
          <stddev>0.001</stddev>
        </noise>
      </ray>
      <always_on>1</always_on>
      <visualize>true</visualize>
    </sensor>
  </gazebo>
  <gazebo>
    <plugin filename="libignition-gazebo-sensors-system.so" name="ignition::gazebo::systems::Sensors">
      <render_engine>ogre2</render_engine>
    </plugin>
  </gazebo>
  <gazebo reference="rplidar_s1_link">
    <material>Gazebo/DarkGrey</material>
  </gazebo>
  <!-- use_gpu has to be set to true, CPU lidar doesn't work in ignition - https://github.com/gazebosim/gz-sensors/issues/26 -->
</robot>