<?xml version="1.0"?>
<!-- =================================================================================== -->
<!-- |    This document was autogenerated by xacro from rosbot.urdf.xacro              | -->
<!-- |    EDITING THIS FILE BY HAND IS NOT RECOMMENDED                                 | -->
<!-- =================================================================================== -->
<robot name="rosbot">
  <link name="base_link" />
  <joint name="base_to_body_joint" type="fixed">
    <origin rpy="0.0 0.0 0.0" xyz="0.0 0.0 0.0425" />
    <parent link="base_link" />
    <child link="body_link" />
  </joint>
  <link name="body_link">
    <visual>
      <geometry>
        <mesh filename="file:///robot_models/rosbot2/meshes/body.stl" scale="0.001 0.001 0.001" />
      </geometry>
      <origin rpy="1.5707963267948966 0.0 1.5707963267948966" xyz="0.0 0.0 -0.0173" />
      <material name="White">
        <color rgba="1.0 1.0 1.0 1.0" />
      </material>
    </visual>
    <collision>
      <geometry>
        <box size="0.197 0.150 0.080" />
      </geometry>
      <origin rpy="0.0 0.0 0.0" xyz="0.0 0.0 0.02" />
    </collision>
    <inertial>
      <mass value="2.0" />
      <inertia ixx="0.001" ixy="0.000" ixz="0.000" iyy="0.001" iyz="0.000" izz="0.001" />
    </inertial>
  </link>
  <gazebo reference="body_link">
    <material>Gazebo/White</material>
  </gazebo>
  <joint name="body_to_cover_joint" type="fixed">
    <origin rpy="0.0 0.0 0.0" xyz="0.0 0.0 0.0603" />
    <parent link="body_link" />
    <child link="cover_link" />
  </joint>
  <link name="cover_link">
    <visual>
      <geometry>
        <mesh filename="file:///robot_models/rosbot2/meshes/cover.stl" scale="0.001 0.001 0.001" />
      </geometry>
      <origin rpy="1.5707963267948966 0.0 1.5707963267948966" xyz="0.0 0.0 -0.002" />
      <material name="Red">
        <color rgba="0.8 0.0 0.0 1.0" />
      </material>
    </visual>
    <gazebo reference="cover_link">
      <material>Gazebo/Red</material>
    </gazebo>
    <inertial>
      <mass value="0.000001" />
      <inertia ixx="1.0" ixy="0.0" ixz="0.0" iyy="1.0" iyz="0.0" izz="0.0" />
    </inertial>
  </link>
  <joint name="body_to_imu_joint" type="fixed">
    <origin rpy="0.0 0.0 0.0" xyz="0.003 -0.0495 0.04332" />
    <parent link="body_link" />
    <child link="imu_link" />
  </joint>
  <link name="imu_link">
    <inertial>
      <mass value="0.001" />
      <inertia ixx="1" ixy="0" ixz="0" iyy="1" iyz="0" izz="1" />
    </inertial>
  </link>
  <joint name="body_to_camera_joint" type="fixed">
    <origin rpy="0.0 0.0 0.0" xyz="-0.0141 0.0 0.125" />
    <parent link="body_link" />
    <child link="camera_link" />
  </joint>
  <link name="camera_link">
    <inertial>
      <mass value="0.000001" />
      <inertia ixx="1" ixy="0" ixz="0" iyy="1" iyz="0" izz="1" />
    </inertial>
  </link>
  <joint name="fl_range_joint" type="fixed">
    <axis xyz="0 1 0" />
    <origin rpy="0 0 0.218 " xyz="0.0926 0.05 0.015" />
    <parent link="body_link" />
    <child link="fl_range" />
  </joint>
  <link name="fl_range" />
  <joint name="fr_range_joint" type="fixed">
    <axis xyz="0 1 0" />
    <origin rpy="0 0 -0.218 " xyz="0.0926 -0.05 0.015" />
    <parent link="body_link" />
    <child link="fr_range" />
  </joint>
  <link name="fr_range" />
  <joint name="rl_range_joint" type="fixed">
    <axis xyz="0 1 0" />
    <origin rpy="0 0 2.924 " xyz="-0.0926 0.05 0.0115" />
    <parent link="body_link" />
    <child link="rl_range" />
  </joint>
  <link name="rl_range" />
  <joint name="rr_range_joint" type="fixed">
    <axis xyz="0 1 0" />
    <origin rpy="0 0 3.360" xyz="-0.0926 -0.05 0.0115" />
    <parent link="body_link" />
    <child link="rr_range" />
  </joint>
  <link name="rr_range" />
  <joint name="fl_wheel_joint" type="continuous">
    <parent link="body_link" />
    <child link="fl_wheel_link" />
    <origin rpy="0.0 0.0 0.0" xyz="0.053 0.096 0.0" />
    <axis xyz="0.0 1.0 0.0" />
    <limit effort="1.5" velocity="5.0" />
    <dynamics damping="0.001" friction="0.001" />
  </joint>
  <link name="fl_wheel_link">
    <visual>
      <geometry>
        <mesh filename="file:///robot_models/rosbot2/meshes/wheel.stl" scale="0.001 0.001 0.001" />
      </geometry>
      <origin rpy="0.0 0.0 1.5707963267948966" xyz="0.0 0.012999999999999998 0.0" />
      <material name="Black">
        <color rgba="0.0 0.0 0.0 1.0" />
      </material>
    </visual>
    <collision>
      <geometry>
        <cylinder length="0.036" radius="0.0425" />
      </geometry>
      <origin rpy="1.5707963267948966 0.0 0.0" xyz="0.0 0.0 0.0" />
    </collision>
    <inertial>
      <mass value="0.100" />
      <inertia ixx="0.001" ixy="0.000" ixz="0.000" iyy="0.001" iyz="0.000" izz="0.001" />
    </inertial>
  </link>
  <gazebo reference="fl_wheel_link">
    <material>Gazebo/DarkGrey</material>
  </gazebo>
  <joint name="fr_wheel_joint" type="continuous">
    <parent link="body_link" />
    <child link="fr_wheel_link" />
    <origin rpy="0.0 0.0 0.0" xyz="0.053 -0.096 0.0" />
    <axis xyz="0.0 1.0 0.0" />
    <limit effort="1.5" velocity="5.0" />
    <dynamics damping="0.001" friction="0.001" />
  </joint>
  <link name="fr_wheel_link">
    <visual>
      <geometry>
        <mesh filename="file:///robot_models/rosbot2/meshes/wheel.stl" scale="0.001 0.001 0.001" />
      </geometry>
      <origin rpy="0.0 0.0 -1.5707963267948966" xyz="0.0 -0.012999999999999998 0.0" />
      <material name="Black">
        <color rgba="0.0 0.0 0.0 1.0" />
      </material>
    </visual>
    <collision>
      <geometry>
        <cylinder length="0.036" radius="0.0425" />
      </geometry>
      <origin rpy="1.5707963267948966 0.0 0.0" xyz="0.0 0.0 0.0" />
    </collision>
    <inertial>
      <mass value="0.100" />
      <inertia ixx="0.001" ixy="0.000" ixz="0.000" iyy="0.001" iyz="0.000" izz="0.001" />
    </inertial>
  </link>
  <gazebo reference="fr_wheel_link">
    <material>Gazebo/DarkGrey</material>
  </gazebo>
  <joint name="rl_wheel_joint" type="continuous">
    <parent link="body_link" />
    <child link="rl_wheel_link" />
    <origin rpy="0.0 0.0 0.0" xyz="-0.053 0.096 0.0" />
    <axis xyz="0.0 1.0 0.0" />
    <limit effort="1.5" velocity="5.0" />
    <dynamics damping="0.001" friction="0.001" />
  </joint>
  <link name="rl_wheel_link">
    <visual>
      <geometry>
        <mesh filename="file:///robot_models/rosbot2/meshes/wheel.stl" scale="0.001 0.001 0.001" />
      </geometry>
      <origin rpy="0.0 0.0 1.5707963267948966" xyz="0.0 0.012999999999999998 0.0" />
      <material name="Black">
        <color rgba="0.0 0.0 0.0 1.0" />
      </material>
    </visual>
    <collision>
      <geometry>
        <cylinder length="0.036" radius="0.0425" />
      </geometry>
      <origin rpy="1.5707963267948966 0.0 0.0" xyz="0.0 0.0 0.0" />
    </collision>
    <inertial>
      <mass value="0.100" />
      <inertia ixx="0.001" ixy="0.000" ixz="0.000" iyy="0.001" iyz="0.000" izz="0.001" />
    </inertial>
  </link>
  <gazebo reference="rl_wheel_link">
    <material>Gazebo/DarkGrey</material>
  </gazebo>
  <joint name="rr_wheel_joint" type="continuous">
    <parent link="body_link" />
    <child link="rr_wheel_link" />
    <origin rpy="0.0 0.0 0.0" xyz="-0.053 -0.096 0.0" />
    <axis xyz="0.0 1.0 0.0" />
    <limit effort="1.5" velocity="5.0" />
    <dynamics damping="0.001" friction="0.001" />
  </joint>
  <link name="rr_wheel_link">
    <visual>
      <geometry>
        <mesh filename="file:///robot_models/rosbot2/meshes/wheel.stl" scale="0.001 0.001 0.001" />
      </geometry>
      <origin rpy="0.0 0.0 -1.5707963267948966" xyz="0.0 -0.012999999999999998 0.0" />
      <material name="Black">
        <color rgba="0.0 0.0 0.0 1.0" />
      </material>
    </visual>
    <collision>
      <geometry>
        <cylinder length="0.036" radius="0.0425" />
      </geometry>
      <origin rpy="1.5707963267948966 0.0 0.0" xyz="0.0 0.0 0.0" />
    </collision>
    <inertial>
      <mass value="0.100" />
      <inertia ixx="0.001" ixy="0.000" ixz="0.000" iyy="0.001" iyz="0.000" izz="0.001" />
    </inertial>
  </link>
  <gazebo reference="rr_wheel_link">
    <material>Gazebo/DarkGrey</material>
  </gazebo>
  <ros2_control name="imu" type="sensor">
    <hardware>
      <plugin>rosbot_hardware_interfaces/RosbotImuSensor</plugin>
      <param name="connection_timeout_ms">120000</param>
      <param name="connection_check_period_ms">500</param>
    </hardware>
    <sensor name="imu">
      <state_interface name="orientation.x" />
      <state_interface name="orientation.y" />
      <state_interface name="orientation.z" />
      <state_interface name="orientation.w" />
      <state_interface name="angular_velocity.x" />
      <state_interface name="angular_velocity.y" />
      <state_interface name="angular_velocity.z" />
      <state_interface name="linear_acceleration.x" />
      <state_interface name="linear_acceleration.y" />
      <state_interface name="linear_acceleration.z" />
    </sensor>
  </ros2_control>
  <ros2_control name="wheels" type="system">
    <hardware>
      <plugin>rosbot_hardware_interfaces/RosbotSystem</plugin>
      <param name="connection_timeout_ms">120000</param>
      <param name="connection_check_period_ms">500</param>
      <!-- for some reason diff drive controller publishes velocities for motors in rad/s, but expects feedback in m/s
            both commands and feedback from digital board are in rad/s, so it is necessary to convert it
            maybe will be resolved (https://github.com/ros-controls/ros2_controllers/issues/411), then it can be removed -->
      <param name="wheel_radius">0.0425</param>
      <!-- order of velocity commands to be published in motors_cmd Float32MultiArray msg -->
      <param name="velocity_command_joint_order">
                rr_wheel_joint,
                rl_wheel_joint,
                fr_wheel_joint,
                fl_wheel_joint
          </param>
    </hardware>
    <joint name="fl_wheel_joint">
      <command_interface name="velocity" />
      <state_interface name="position" />
      <state_interface name="velocity" />
    </joint>
    <joint name="fr_wheel_joint">
      <command_interface name="velocity" />
      <state_interface name="position" />
      <state_interface name="velocity" />
    </joint>
    <joint name="rl_wheel_joint">
      <command_interface name="velocity" />
      <state_interface name="position" />
      <state_interface name="velocity" />
    </joint>
    <joint name="rr_wheel_joint">
      <command_interface name="velocity" />
      <state_interface name="position" />
      <state_interface name="velocity" />
    </joint>
  </ros2_control>
  <joint name="cover_link_to_rplidar_a2_link_joint" type="fixed">
    <origin rpy="0.0 0.0 -3.141592653589793" xyz="0.02 0.0 0.0" />
    <parent link="cover_link" />
    <child link="rplidar_a2_link" />
  </joint>
  <link name="rplidar_a2_link">
    <visual>
      <geometry>
        <mesh filename="file:///robot_models/rosbot2/meshes/rplidar.stl" scale="0.001 0.001 0.001" />
      </geometry>
      <origin rpy="1.5707963267948966 0.0 -1.5707963267948966" xyz="0.0 0.0 0.0" />
      <material name="Black">
        <color rgba="0.0 0.0 0.0 1.0" />
      </material>
    </visual>
    <collision>
      <geometry>
        <cylinder length="0.0408" radius="0.03625" />
      </geometry>
      <origin rpy="0 0 0" xyz="0 0 0.0204" />
    </collision>
    <inertial>
      <mass value="0.190" />
      <inertia ixx="0.001" ixy="0" ixz="0" iyy="0.001" iyz="0" izz="0.001" />
    </inertial>
  </link>
  <gazebo reference="rplidar_a2_link">
    <material>Gazebo/DarkGrey</material>
  </gazebo>
  <joint name="laser_joint" type="fixed">
    <origin rpy="0.0 0.0 0.0" xyz="0.0 0.0 0.0335" />
    <parent link="rplidar_a2_link" />
    <child link="laser" />
  </joint>
  <link name="laser" />
  <gazebo reference="laser">
    <sensor name="rplidar_a2_sensor" type="ray">
      <topic>scan</topic>
      <frame_id>laser</frame_id>
      <ignition_frame_id>laser</ignition_frame_id>
      <update_rate>10</update_rate>
      <ray>
        <scan>
          <horizontal>
            <samples>400</samples>
            <resolution>1</resolution>
            <min_angle>-3.141592653589793</min_angle>
            <max_angle>3.141592653589793</max_angle>
          </horizontal>
        </scan>
        <range>
          <min>0.2</min>
          <max>16.0</max>
          <resolution>0.08</resolution>
        </range>
        <noise>
          <type>gaussian</type>
          <mean>0.05</mean>
          <stddev>0.01</stddev>
        </noise>
      </ray>
      <always_on>1</always_on>
      <visualize>false</visualize>
    </sensor>
  </gazebo>
  <gazebo>
    <plugin filename="libgazebo_ros_ray_sensor.so" name="scan">
      <ros>
        <namespace>/</namespace>
        <argument>~/out:=scan</argument>
      </ros>
      <output_type>sensor_msgs/LaserScan</output_type>
      <frame_name>laser</frame_name>
    </plugin>
  </gazebo>
  <joint name="body_to_orbbec_astra_joint" type="fixed">
    <origin rpy="0.0 0.0 0.0" xyz="0.0 0.0 0.0" />
    <parent link="camera_link" />
    <child link="orbbec_astra_link" />
  </joint>
  <link name="orbbec_astra_link">
    <visual>
      <geometry>
        <mesh filename="file:///robot_models/rosbot2/meshes/astra.stl" scale="0.001 0.001 0.001" />
      </geometry>
      <origin rpy="1.5707963267948966 0 1.5707963267948966" xyz="-0.01 0 0.0277" />
      <material name="Black">
        <color rgba="0.0 0.0 0.0 1.0" />
      </material>
    </visual>
    <collision>
      <geometry>
        <box size="0.165 0.04 0.05" />
      </geometry>
      <origin rpy="0 0 1.5707963267948966" xyz="-0.01 0 0.025" />
    </collision>
    <inertial>
      <mass value="0.105" />
      <inertia ixx="0.001" ixy="0" ixz="0" iyy="0.001" iyz="0" izz="0.001" />
    </inertial>
  </link>
  <joint name="orbbec_astra_depth_joint" type="fixed">
    <origin rpy="0.0 1.5707963267948966 0.0" xyz="0.01 0 0.035" />
    <parent link="orbbec_astra_link" />
    <child link="orbbec_astra_depth_link" />
  </joint>
  <link name="orbbec_astra_depth_link" />
  <gazebo reference="orbbec_astra_link">
    <material>Gazebo/DarkGrey</material>
  </gazebo>
  <joint name="orbbec_astra_depth_reference_joint" type="fixed">
    <origin rpy="1.5707963267948966 -1.5707963267948966 0.0" xyz="0.0 0.0 0.0" />
    <parent link="orbbec_astra_depth_link" />
    <child link="orbbec_astra_depth_reference_link" />
  </joint>
  <link name="orbbec_astra_depth_reference_link" />
  <gazebo reference="orbbec_astra_depth_reference_link">
    <sensor name="orbbec_astra_camera" type="depth">
      <always_on>1</always_on>
      <update_rate>10</update_rate>
      <camera name="camera">
        <distortion>
          <k1>0.07</k1>
          <k2>0.00</k2>
          <k3>0.00</k3>
          <p1>0.00</p1>
          <p2>0.00</p2>
          <center>0.0 0.0</center>
        </distortion>
      </camera>
      <plugin filename="libgazebo_ros_camera.so" name="rgbd_camera">
        <ros>
          <namespace>orbbec_astra_camera</namespace>
          <argument>--ros-args --remap custom_camera/image_raw:=rgb/image_raw</argument>
          <argument>--ros-args --remap custom_camera/image_depth:=depth/image_raw</argument>
          <argument>--ros-args --remap custom_camera/camera_info:=rgb/camera_info</argument>
          <argument>--ros-args --remap custom_camera/camera_info_depth:=depth/camera_info</argument>
          <argument>--ros-args --remap custom_camera/points:=depth/points</argument>
        </ros>
        <camera_name>camera</camera_name>
        <frame_name>orbbec_astra_depth_link</frame_name>
        <hack_baseline>0.07</hack_baseline>
        <min_depth>0.6</min_depth>
        <max_depth>8.0</max_depth>
      </plugin>
    </sensor>
  </gazebo>
</robot>